Workbook
Name cookings_oils: 'macros and basic'!#REF!
Name dairy: 'macros and basic'!$H$2:$H$1048576
Name drinks: 'macros and basic'!#REF!
Name Fruits: 'macros and basic'!#REF!
Name grains: 'macros and basic'!#REF!
Name legumes: 'macros and basic'!#REF!
Name masala: 'macros and basic'!#REF!
Name masala: [1]Sheet1!#REF!
Name non_veg: 'macros and basic'!#REF!
Name Nuts_and_seeds: 'macros and basic'!#REF!
Name Particulars: 'macros and basic'!$B$2:$B$1048576
Name seeds: 'macros and basic'!#REF!
Name seeds: [1]Sheet1!#REF!
Name supplements: 'macros and basic'!$G$2:$G$1048576
Name Vegetables: 'macros and basic'!#REF!

Sheet inputs
A1: ENTER VALUES IN GMS AND HOW MANY TIMES IN A WEEK
C3: dairy | H3: grains
A4: Name | B4: Qty | C4: Units | D4: No of times in a week | F4: Name | G4: Qty | H4: Units | I4: No of times in a week
A5: whey | B5: 100 | C5: gm | D5: 1 | F5: white (rice) | G5: 70 | H5: gm | I5: 7
A6: milk | B6: 150 | C6: ml | D6: 7 | F6: oats | G6: 30 | H6: gm | I6: 7
A7: skim powder | B7: 20 | C7: gm | D7: 7 | F7: chia | G7: 7 | H7: gm | I7: 50
C8: legumes | F8: flax | G8: 10 | H8: gm | I8: 7
A9: roasted chana | B9: 50 | C9: gm | D9: 5 | H9: Non veg
A10: yellow moong | B10: 50 | C10: gm | D10: 1 | F10: eggs | G10: 55 | H10: piece | I10: 8
A11: green moong | B11: 50 | C11: gm | D11: 1 | F11: chicken | G11: 200 | H11: gm | I11: 4
A12: masoor | B12: 50 | C12: gm | D12: 1
A13: rajma | B13: 50 | C13: gm | D13: 1
A14: chana | B14: 50 | C14: gm | D14: 1
A15: soya chunks | B15: 50 | C15: gm | D15: 5

Sheet macros and basic
B1: Particulars
A2: vitamins | B2: soluble | C2: unit | D2: rda | E2: optimal | G2: whey | H2: milk | I2: skim milk powder | J2: oats | K2: chia | L2: flax | M2: eggs | N2: chicken | O2: soya chunks | P2: roasted chana | Q2: white (rice) | R2: yellow moong | S2: green moong | T2: masoor | U2: rajma | V2: chana | W2: carrot | X2: pomegranate | Y2: beetroot | Z2: tomato | AA2: guava | AB2: total week | AC2: per day avg | AD2: per day vs rda | AE2: unit | AF2: percentage consume | AG2: per day vs optimal | AH2: unit | AI2: percent consume
A3: A (retinol only) | B3: fat | C3: mcg | D3: 900 | E3: 1200 | G3: =IFERROR((inputs!$B$5/100) *'master data '!E2 * inputs!$D$5,0) -> 0 | H3: =IFERROR((inputs!$B$6/100) *'master data '!F2 * inputs!$D$6,0) -> 525 | I3: =IFERROR((inputs!$B$7/100) *'master data '!G2 * inputs!$D$7,0) -> 63 | J3: =IFERROR((inputs!$G$6/100) *'master data '!H2 * inputs!$I$6,0) -> 0 | K3: =IFERROR((inputs!$G$7/100) *'master data '!I2 * inputs!$I$7,0) -> 0 | L3: =IFERROR((inputs!$G$8/100) *'master data '!J2 * inputs!$I$8,0) -> 0 | M3: =IFERROR((inputs!$G$10/100) *'master data '!K2 * inputs!$I$10,0) -> 704 | N3: =IFERROR((inputs!$G$11/100) *'master data '!L2 * inputs!$I$11,0) -> 40 | O3: =IFERROR((inputs!$B$15/100) *'master data '!M2 * inputs!$D$15,0) -> 0 | P3: =IFERROR((inputs!$B$9/100) *'master data '!N2 * inputs!$D$9,0) -> 0 | Q3: =IFERROR((inputs!$G$5/100) *'master data '!O2 * inputs!$I$5,0) -> 0 | R3: =IFERROR((inputs!$B$10/100) *'master data '!P2 * inputs!$D$10,0) -> 0 | S3: =IFERROR((inputs!$B$11/100) *'master data '!Q2 * inputs!$D$11,0) -> 0 | T3: =IFERROR((inputs!$B$12/100) *'master data '!R2 * inputs!$D$12,0) -> 0 | U3: =IFERROR((inputs!$B$13/100) *'master data '!S2 * inputs!$D$13,0) -> 0 | V3: =IFERROR((inputs!$B$14/100) *'master data '!T2 * inputs!$D$14,0) -> 0 | W3: =IFERROR((#REF!/100) *'master data '!U2 *#REF!,0) -> 0 | X3: =IFERROR((#REF!/100) *'master data '!W2 *#REF!,0) -> 0 | Y3: =IFERROR((#REF!/100) *'master data '!X2 *#REF!,0) -> 0 | Z3: =IFERROR((#REF!/100) *'master data '!V2 *#REF!,0) -> 0 | AA3: =IFERROR((#REF!/100) *'master data '!Y2 *#REF!,0) -> 0 | AB3: =SUM(G3:AA3) -> 1332 | AC3: =AB3 /7 -> 190.28571 | AD3: =AC3 - D3 -> -709.71429 | AE3: mcg | AF3: =IFERROR(AC3/D3*100,"N/A") -> 21.142857 | AG3: =AC3 -E3 -> -1009.7143 | AH3: mcg | AI3: =AC3 /E3*100 -> 15.857143
A4: B1 (Thiamine) | B4: water | C4: mg | D4: 1.2 | E4: 2 | G4: =IFERROR((inputs!$B$5/100) *'master data '!E3 * inputs!$D$5,0) -> 0.42 | H4: =IFERROR((inputs!$B$6/100) *'master data '!F3 * inputs!$D$6,0) -> 0.42 | I4: =IFERROR((inputs!$B$7/100) *'master data '!G3 * inputs!$D$7,0) -> 0.56 | J4: =IFERROR((inputs!$G$6/100) *'master data '!H3 * inputs!$I$6,0) -> 0.966 | K4: =IFERROR((inputs!$G$7/100) *'master data '!I3 * inputs!$I$7,0) -> 2.1 | L4: =IFERROR((inputs!$G$8/100) *'master data '!J3 * inputs!$I$8,0) -> 0.35 | M4: =IFERROR((inputs!$G$10/100) *'master data '!K3 * inputs!$I$10,0) -> 0.352 | N4: =IFERROR((inputs!$G$11/100) *'master data '!L3 * inputs!$I$11,0) -> 0.56 | O4: =IFERROR((inputs!$B$15/100) *'master data '!M3 * inputs!$D$15,0) -> 2.175 | P4: =IFERROR((inputs!$B$9/100) *'master data '!N3 * inputs!$D$9,0) -> 0.7 | Q4: =IFERROR((inputs!$G$5/100) *'master data '!O3 * inputs!$I$5,0) -> 0.49 | R4: =IFERROR((inputs!$B$10/100) *'master data '!P3 * inputs!$D$10,0) -> 0.21 | S4: =IFERROR((inputs!$B$11/100) *'master data '!Q3 * inputs!$D$11,0) -> 0.31 | T4: =IFERROR((inputs!$B$12/100) *'master data '!R3 * inputs!$D$12,0) -> 0.25 | U4: =IFERROR((inputs!$B$13/100) *'master data '!S3 * inputs!$D$13,0) -> 0.225 | V4: =IFERROR((inputs!$B$14/100) *'master data '!T3 * inputs!$D$14,0) -> 0.24 | W4: =IFERROR((#REF!/100) *'master data '!U3 *#REF!,0) -> 0 | X4: =IFERROR((#REF!/100) *'master data '!W3 *#REF!,0) -> 0 | Y4: =IFERROR((#REF!/100) *'master data '!X3 *#REF!,0) -> 0 | Z4: =IFERROR((#REF!/100) *'master data '!V3 *#REF!,0) -> 0 | AA4: =IFERROR((#REF!/100) *'master data '!Y3 *#REF!,0) -> 0 | AB4: =SUM(G4:AA4) -> 10.328 | AC4: =AB4 /7 -> 1.4754286 | AD4: =AC4 - D4 -> 0.27542857 | AE4: mg | AF4: =IFERROR(AC4/D4*100,"N/A") -> 122.95238 | AG4: =AC4 -E4 -> -0.52457143 | AH4: mg | AI4: =AC4 /E4*100 -> 73.771429
A5: B2 (Riboflavin) | B5: water | C5: mg | D5: 1.3 | E5: 2 | G5: =IFERROR((inputs!$B$5/100) *'master data '!E4 * inputs!$D$5,0) -> 0.48 | H5: =IFERROR((inputs!$B$6/100) *'master data '!F4 * inputs!$D$6,0) -> 1.995 | I5: =IFERROR((inputs!$B$7/100) *'master data '!G4 * inputs!$D$7,0) -> 2.8 | J5: =IFERROR((inputs!$G$6/100) *'master data '!H4 * inputs!$I$6,0) -> 0.231 | K5: =IFERROR((inputs!$G$7/100) *'master data '!I4 * inputs!$I$7,0) -> 0.7 | L5: =IFERROR((inputs!$G$8/100) *'master data '!J4 * inputs!$I$8,0) -> 0.14 | M5: =IFERROR((inputs!$G$10/100) *'master data '!K4 * inputs!$I$10,0) -> 1.936 | N5: =IFERROR((inputs!$G$11/100) *'master data '!L4 * inputs!$I$11,0) -> 0.8 | O5: =IFERROR((inputs!$B$15/100) *'master data '!M4 * inputs!$D$15,0) -> 0.725 | P5: =IFERROR((inputs!$B$9/100) *'master data '!N4 * inputs!$D$9,0) -> 0.25 | Q5: =IFERROR((inputs!$G$5/100) *'master data '!O4 * inputs!$I$5,0) -> 0.196 | R5: =IFERROR((inputs!$B$10/100) *'master data '!P4 * inputs!$D$10,0) -> 0.1 | S5: =IFERROR((inputs!$B$11/100) *'master data '!Q4 * inputs!$D$11,0) -> 0.115 | T5: =IFERROR((inputs!$B$12/100) *'master data '!R4 * inputs!$D$12,0) -> 0.105 | U5: =IFERROR((inputs!$B$13/100) *'master data '!S4 * inputs!$D$13,0) -> 0.11 | V5: =IFERROR((inputs!$B$14/100) *'master data '!T4 * inputs!$D$14,0) -> 0.09 | W5: =IFERROR((#REF!/100) *'master data '!U4 *#REF!,0) -> 0 | X5: =IFERROR((#REF!/100) *'master data '!W4 *#REF!,0) -> 0 | Y5: =IFERROR((#REF!/100) *'master data '!X4 *#REF!,0) -> 0 | Z5: =IFERROR((#REF!/100) *'master data '!V4 *#REF!,0) -> 0 | AA5: =IFERROR((#REF!/100) *'master data '!Y4 *#REF!,0) -> 0 | AB5: =SUM(G5:AA5) -> 10.773 | AC5: =AB5 /7 -> 1.539 | AD5: =AC5 - D5 -> 0.239 | AE5: mg | AF5: =IFERROR(AC5/D5*100,"N/A") -> 118.38462 | AG5: =AC5 -E5 -> -0.461 | AH5: mg | AI5: =AC5 /E5*100 -> 76.95
A6: B3 (Niacin) | B6: water | C6: mg | D6: 16 | E6: 25 | G6: =IFERROR((inputs!$B$5/100) *'master data '!E5 * inputs!$D$5,0) -> 5.4 | H6: =IFERROR((inputs!$B$6/100) *'master data '!F5 * inputs!$D$6,0) -> 1.05 | I6: =IFERROR((inputs!$B$7/100) *'master data '!G5 * inputs!$D$7,0) -> 1.4 | J6: =IFERROR((inputs!$G$6/100) *'master data '!H5 * inputs!$I$6,0) -> 2.1 | K6: =IFERROR((inputs!$G$7/100) *'master data '!I5 * inputs!$I$7,0) -> 10.85 | L6: =IFERROR((inputs!$G$8/100) *'master data '!J5 * inputs!$I$8,0) -> 2.17 | M6: =IFERROR((inputs!$G$10/100) *'master data '!K5 * inputs!$I$10,0) -> 0.44 | N6: =IFERROR((inputs!$G$11/100) *'master data '!L5 * inputs!$I$11,0) -> 86.4 | O6: =IFERROR((inputs!$B$15/100) *'master data '!M5 * inputs!$D$15,0) -> 4 | P6: =IFERROR((inputs!$B$9/100) *'master data '!N5 * inputs!$D$9,0) -> 4 | Q6: =IFERROR((inputs!$G$5/100) *'master data '!O5 * inputs!$I$5,0) -> 7.35 | R6: =IFERROR((inputs!$B$10/100) *'master data '!P5 * inputs!$D$10,0) -> 1.05 | S6: =IFERROR((inputs!$B$11/100) *'master data '!Q5 * inputs!$D$11,0) -> 1.1 | T6: =IFERROR((inputs!$B$12/100) *'master data '!R5 * inputs!$D$12,0) -> 1.3 | U6: =IFERROR((inputs!$B$13/100) *'master data '!S5 * inputs!$D$13,0) -> 1.05 | V6: =IFERROR((inputs!$B$14/100) *'master data '!T5 * inputs!$D$14,0) -> 0.8 | W6: =IFERROR((#REF!/100) *'master data '!U5 *#REF!,0) -> 0 | X6: =IFERROR((#REF!/100) *'master data '!W5 *#REF!,0) -> 0 | Y6: =IFERROR((#REF!/100) *'master data '!X5 *#REF!,0) -> 0 | Z6: =IFERROR((#REF!/100) *'master data '!V5 *#REF!,0) -> 0 | AA6: =IFERROR((#REF!/100) *'master data '!Y5 *#REF!,0) -> 0 | AB6: =SUM(G6:AA6) -> 130.46 | AC6: =AB6 /7 -> 18.637143 | AD6: =AC6 - D6 -> 2.6371429 | AE6: mg | AF6: =IFERROR(AC6/D6*100,"N/A") -> 116.48214 | AG6: =AC6 -E6 -> -6.3628571 | AH6: mg | AI6: =AC6 /E6*100 -> 74.548571
A7: B5 (Pantothenic Acid) | B7: water | C7: mg | D7: 5 | E7: 10 | G7: =IFERROR((inputs!$B$5/100) *'master data '!E6 * inputs!$D$5,0) -> 1.5 | H7: =IFERROR((inputs!$B$6/100) *'master data '!F6 * inputs!$D$6,0) -> 3.465 | I7: =IFERROR((inputs!$B$7/100) *'master data '!G6 * inputs!$D$7,0) -> 4.2 | J7: =IFERROR((inputs!$G$6/100) *'master data '!H6 * inputs!$I$6,0) -> 2.31 | K7: =IFERROR((inputs!$G$7/100) *'master data '!I6 * inputs!$I$7,0) -> 1.75 | L7: =IFERROR((inputs!$G$8/100) *'master data '!J6 * inputs!$I$8,0) -> 0.35 | M7: =IFERROR((inputs!$G$10/100) *'master data '!K6 * inputs!$I$10,0) -> 6.16 | N7: =IFERROR((inputs!$G$11/100) *'master data '!L6 * inputs!$I$11,0) -> 8 | O7: =IFERROR((inputs!$B$15/100) *'master data '!M6 * inputs!$D$15,0) -> 0.375 | P7: =IFERROR((inputs!$B$9/100) *'master data '!N6 * inputs!$D$9,0) -> 1.25 | Q7: =IFERROR((inputs!$G$5/100) *'master data '!O6 * inputs!$I$5,0) -> 3.92 | R7: =IFERROR((inputs!$B$10/100) *'master data '!P6 * inputs!$D$10,0) -> 0.55 | S7: =IFERROR((inputs!$B$11/100) *'master data '!Q6 * inputs!$D$11,0) -> 0.65 | T7: =IFERROR((inputs!$B$12/100) *'master data '!R6 * inputs!$D$12,0) -> 0.6 | U7: =IFERROR((inputs!$B$13/100) *'master data '!S6 * inputs!$D$13,0) -> 0.55 | V7: =IFERROR((inputs!$B$14/100) *'master data '!T6 * inputs!$D$14,0) -> 0.5 | W7: =IFERROR((#REF!/100) *'master data '!U6 *#REF!,0) -> 0 | X7: =IFERROR((#REF!/100) *'master data '!W6 *#REF!,0) -> 0 | Y7: =IFERROR((#REF!/100) *'master data '!X6 *#REF!,0) -> 0 | Z7: =IFERROR((#REF!/100) *'master data '!V6 *#REF!,0) -> 0 | AA7: =IFERROR((#REF!/100) *'master data '!Y6 *#REF!,0) -> 0 | AB7: =SUM(G7:AA7) -> 36.13 | AC7: =AB7 /7 -> 5.1614286 | AD7: =AC7 - D7 -> 0.16142857 | AE7: mg | AF7: =IFERROR(AC7/D7*100,"N/A") -> 103.22857 | AG7: =AC7 -E7 -> -4.8385714 | AH7: mg | AI7: =AC7 /E7*100 -> 51.614286
A8: B6 (pyridoxine) | B8: water | C8: mg | D8: 1.3 | E8: 3 | G8: =IFERROR((inputs!$B$5/100) *'master data '!E7 * inputs!$D$5,0) -> 0.6 | H8: =IFERROR((inputs!$B$6/100) *'master data '!F7 * inputs!$D$6,0) -> 0.42 | I8: =IFERROR((inputs!$B$7/100) *'master data '!G7 * inputs!$D$7,0) -> 0.56 | J8: =IFERROR((inputs!$G$6/100) *'master data '!H7 * inputs!$I$6,0) -> 0.252 | K8: =IFERROR((inputs!$G$7/100) *'master data '!I7 * inputs!$I$7,0) -> 2.1 | L8: =IFERROR((inputs!$G$8/100) *'master data '!J7 * inputs!$I$8,0) -> 0.35 | M8: =IFERROR((inputs!$G$10/100) *'master data '!K7 * inputs!$I$10,0) -> 0.44 | N8: =IFERROR((inputs!$G$11/100) *'master data '!L7 * inputs!$I$11,0) -> 4.8 | O8: =IFERROR((inputs!$B$15/100) *'master data '!M7 * inputs!$D$15,0) -> 0.925 | P8: =IFERROR((inputs!$B$9/100) *'master data '!N7 * inputs!$D$9,0) -> 0.875 | Q8: =IFERROR((inputs!$G$5/100) *'master data '!O7 * inputs!$I$5,0) -> 0.735 | R8: =IFERROR((inputs!$B$10/100) *'master data '!P7 * inputs!$D$10,0) -> 0.27 | S8: =IFERROR((inputs!$B$11/100) *'master data '!Q7 * inputs!$D$11,0) -> 0.29 | T8: =IFERROR((inputs!$B$12/100) *'master data '!R7 * inputs!$D$12,0) -> 0.27 | U8: =IFERROR((inputs!$B$13/100) *'master data '!S7 * inputs!$D$13,0) -> 0.205 | V8: =IFERROR((inputs!$B$14/100) *'master data '!T7 * inputs!$D$14,0) -> 0.265 | W8: =IFERROR((#REF!/100) *'master data '!U7 *#REF!,0) -> 0 | X8: =IFERROR((#REF!/100) *'master data '!W7 *#REF!,0) -> 0 | Y8: =IFERROR((#REF!/100) *'master data '!X7 *#REF!,0) -> 0 | Z8: =IFERROR((#REF!/100) *'master data '!V7 *#REF!,0) -> 0 | AA8: =IFERROR((#REF!/100) *'master data '!Y7 *#REF!,0) -> 0 | AB8: =SUM(G8:AA8) -> 13.357 | AC8: =AB8 /7 -> 1.9081429 | AD8: =AC8 - D8 -> 0.60814286 | AE8: mg | AF8: =IFERROR(AC8/D8*100,"N/A") -> 146.78022 | AG8: =AC8 -E8 -> -1.0918571 | AH8: mg | AI8: =AC8 /E8*100 -> 63.604762
A9: B7(biotin) | B9: water | C9: mcg | D9: 30 | E9: 100 | G9: =IFERROR((inputs!$B$5/100) *'master data '!E8 * inputs!$D$5,0) -> 9 | H9: =IFERROR((inputs!$B$6/100) *'master data '!F8 * inputs!$D$6,0) -> 31.5 | I9: =IFERROR((inputs!$B$7/100) *'master data '!G8 * inputs!$D$7,0) -> 28 | J9: =IFERROR((inputs!$G$6/100) *'master data '!H8 * inputs!$I$6,0) -> 42 | K9: =IFERROR((inputs!$G$7/100) *'master data '!I8 * inputs!$I$7,0) -> 0 | L9: =IFERROR((inputs!$G$8/100) *'master data '!J8 * inputs!$I$8,0) -> 0 | M9: =IFERROR((inputs!$G$10/100) *'master data '!K8 * inputs!$I$10,0) -> 44 | N9: =IFERROR((inputs!$G$11/100) *'master data '!L8 * inputs!$I$11,0) -> 40 | O9: =IFERROR((inputs!$B$15/100) *'master data '!M8 * inputs!$D$15,0) -> 17.5 | P9: =IFERROR((inputs!$B$9/100) *'master data '!N8 * inputs!$D$9,0) -> 12.5 | Q9: =IFERROR((inputs!$G$5/100) *'master data '!O8 * inputs!$I$5,0) -> 9.8 | R9: =IFERROR((inputs!$B$10/100) *'master data '!P8 * inputs!$D$10,0) -> 3 | S9: =IFERROR((inputs!$B$11/100) *'master data '!Q8 * inputs!$D$11,0) -> 3.5 | T9: =IFERROR((inputs!$B$12/100) *'master data '!R8 * inputs!$D$12,0) -> 3 | U9: =IFERROR((inputs!$B$13/100) *'master data '!S8 * inputs!$D$13,0) -> 2.5 | V9: =IFERROR((inputs!$B$14/100) *'master data '!T8 * inputs!$D$14,0) -> 3 | W9: =IFERROR((#REF!/100) *'master data '!U8 *#REF!,0) -> 0 | X9: =IFERROR((#REF!/100) *'master data '!W8 *#REF!,0) -> 0 | Y9: =IFERROR((#REF!/100) *'master data '!X8 *#REF!,0) -> 0 | Z9: =IFERROR((#REF!/100) *'master data '!V8 *#REF!,0) -> 0 | AA9: =IFERROR((#REF!/100) *'master data '!Y8 *#REF!,0) -> 0 | AB9: =SUM(G9:AA9) -> 249.3 | AC9: =AB9 /7 -> 35.614286 | AD9: =AC9 - D9 -> 5.6142857 | AE9: mcg | AF9: =IFERROR(AC9/D9*100,"N/A") -> 118.71429 | AG9: =AC9 -E9 -> -64.385714 | AH9: mcg | AI9: =AC9 /E9*100 -> 35.614286
A10: B9(folate) | B10: water | C10: mcg | D10: 400 | E10: 600 | G10: =IFERROR((inputs!$B$5/100) *'master data '!E9 * inputs!$D$5,0) -> 300 | H10: =IFERROR((inputs!$B$6/100) *'master data '!F9 * inputs!$D$6,0) -> 52.5 | I10: =IFERROR((inputs!$B$7/100) *'master data '!G9 * inputs!$D$7,0) -> 63 | J10: =IFERROR((inputs!$G$6/100) *'master data '!H9 * inputs!$I$6,0) -> 117.6 | K10: =IFERROR((inputs!$G$7/100) *'master data '!I9 * inputs!$I$7,0) -> 304.5 | L10: =IFERROR((inputs!$G$8/100) *'master data '!J9 * inputs!$I$8,0) -> 60.9 | M10: =IFERROR((inputs!$G$10/100) *'master data '!K9 * inputs!$I$10,0) -> 206.8 | N10: =IFERROR((inputs!$G$11/100) *'master data '!L9 * inputs!$I$11,0) -> 32 | O10: =IFERROR((inputs!$B$15/100) *'master data '!M9 * inputs!$D$15,0) -> 500 | P10: =IFERROR((inputs!$B$9/100) *'master data '!N9 * inputs!$D$9,0) -> 450 | Q10: =IFERROR((inputs!$G$5/100) *'master data '!O9 * inputs!$I$5,0) -> 39.2 | R10: =IFERROR((inputs!$B$10/100) *'master data '!P9 * inputs!$D$10,0) -> 312.5 | S10: =IFERROR((inputs!$B$11/100) *'master data '!Q9 * inputs!$D$11,0) -> 320 | T10: =IFERROR((inputs!$B$12/100) *'master data '!R9 * inputs!$D$12,0) -> 240 | U10: =IFERROR((inputs!$B$13/100) *'master data '!S9 * inputs!$D$13,0) -> 197.5 | V10: =IFERROR((inputs!$B$14/100) *'master data '!T9 * inputs!$D$14,0) -> 275 | W10: =IFERROR((#REF!/100) *'master data '!U9 *#REF!,0) -> 0 | X10: =IFERROR((#REF!/100) *'master data '!W9 *#REF!,0) -> 0 | Y10: =IFERROR((#REF!/100) *'master data '!X9 *#REF!,0) -> 0 | Z10: =IFERROR((#REF!/100) *'master data '!V9 *#REF!,0) -> 0 | AA10: =IFERROR((#REF!/100) *'master data '!Y9 *#REF!,0) -> 0 | AB10: =SUM(G10:AA10) -> 3471.5 | AC10: =AB10 /7 -> 495.92857 | AD10: =AC10 - D10 -> 95.928571 | AE10: mcg | AF10: =IFERROR(AC10/D10*100,"N/A") -> 123.98214 | AG10: =AC10 -E10 -> -104.07143 | AH10: mcg | AI10: =AC10 /E10*100 -> 82.654762
A11: B12 | B11: water | C11: mcg | D11: 2.4 | E11: 10 | G11: =IFERROR((inputs!$B$5/100) *'master data '!E10 * inputs!$D$5,0) -> 0 | H11: =IFERROR((inputs!$B$6/100) *'master data '!F10 * inputs!$D$6,0) -> 3.78 | I11: =IFERROR((inputs!$B$7/100) *'master data '!G10 * inputs!$D$7,0) -> 5.6 | J11: =IFERROR((inputs!$G$6/100) *'master data '!H10 * inputs!$I$6,0) -> 0 | K11: =IFERROR((inputs!$G$7/100) *'master data '!I10 * inputs!$I$7,0) -> 0 | L11: =IFERROR((inputs!$G$8/100) *'master data '!J10 * inputs!$I$8,0) -> 0 | M11: =IFERROR((inputs!$G$10/100) *'master data '!K10 * inputs!$I$10,0) -> 4.84 | N11: =IFERROR((inputs!$G$11/100) *'master data '!L10 * inputs!$I$11,0) -> 2.4 | O11: =IFERROR((inputs!$B$15/100) *'master data '!M10 * inputs!$D$15,0) -> 0 | P11: =IFERROR((inputs!$B$9/100) *'master data '!N10 * inputs!$D$9,0) -> 0 | Q11: =IFERROR((inputs!$G$5/100) *'master data '!O10 * inputs!$I$5,0) -> 0 | R11: =IFERROR((inputs!$B$10/100) *'master data '!P10 * inputs!$D$10,0) -> 0 | S11: =IFERROR((inputs!$B$11/100) *'master data '!Q10 * inputs!$D$11,0) -> 0 | T11: =IFERROR((inputs!$B$12/100) *'master data '!R10 * inputs!$D$12,0) -> 0 | U11: =IFERROR((inputs!$B$13/100) *'master data '!S10 * inputs!$D$13,0) -> 0 | V11: =IFERROR((inputs!$B$14/100) *'master data '!T10 * inputs!$D$14,0) -> 0 | W11: =IFERROR((#REF!/100) *'master data '!U10 *#REF!,0) -> 0 | X11: =IFERROR((#REF!/100) *'master data '!W10 *#REF!,0) -> 0 | Y11: =IFERROR((#REF!/100) *'master data '!X10 *#REF!,0) -> 0 | Z11: =IFERROR((#REF!/100) *'master data '!V10 *#REF!,0) -> 0 | AA11: =IFERROR((#REF!/100) *'master data '!Y10 *#REF!,0) -> 0 | AB11: =SUM(G11:AA11) -> 16.62 | AC11: =AB11 /7 -> 2.3742857 | AD11: =AC11 - D11 -> -0.025714286 | AE11: mcg | AF11: =IFERROR(AC11/D11*100,"N/A") -> 98.928571 | AG11: =AC11 -E11 -> -7.6257143 | AH11: mcg | AI11: =AC11 /E11*100 -> 23.742857
A12: C | B12: water | C12: mg | D12: 90 | E12: 500 | G12: =IFERROR((inputs!$B$5/100) *'master data '!E11 * inputs!$D$5,0) -> 12 | H12: =IFERROR((inputs!$B$6/100) *'master data '!F11 * inputs!$D$6,0) -> 10.5 | I12: =IFERROR((inputs!$B$7/100) *'master data '!G11 * inputs!$D$7,0) -> 7 | J12: =IFERROR((inputs!$G$6/100) *'master data '!H11 * inputs!$I$6,0) -> 0 | K12: =IFERROR((inputs!$G$7/100) *'master data '!I11 * inputs!$I$7,0) -> 5.6 | L12: =IFERROR((inputs!$G$8/100) *'master data '!J11 * inputs!$I$8,0) -> 1.12 | M12: =IFERROR((inputs!$G$10/100) *'master data '!K11 * inputs!$I$10,0) -> 0 | N12: =IFERROR((inputs!$G$11/100) *'master data '!L11 * inputs!$I$11,0) -> 0 | O12: =IFERROR((inputs!$B$15/100) *'master data '!M11 * inputs!$D$15,0) -> 0 | P12: =IFERROR((inputs!$B$9/100) *'master data '!N11 * inputs!$D$9,0) -> 7.5 | Q12: =IFERROR((inputs!$G$5/100) *'master data '!O11 * inputs!$I$5,0) -> 0 | R12: =IFERROR((inputs!$B$10/100) *'master data '!P11 * inputs!$D$10,0) -> 2 | S12: =IFERROR((inputs!$B$11/100) *'master data '!Q11 * inputs!$D$11,0) -> 2 | T12: =IFERROR((inputs!$B$12/100) *'master data '!R11 * inputs!$D$12,0) -> 2 | U12: =IFERROR((inputs!$B$13/100) *'master data '!S11 * inputs!$D$13,0) -> 1.5 | V12: =IFERROR((inputs!$B$14/100) *'master data '!T11 * inputs!$D$14,0) -> 2 | W12: =IFERROR((#REF!/100) *'master data '!U11 *#REF!,0) -> 0 | X12: =IFERROR((#REF!/100) *'master data '!W11 *#REF!,0) -> 0 | Y12: =IFERROR((#REF!/100) *'master data '!X11 *#REF!,0) -> 0 | Z12: =IFERROR((#REF!/100) *'master data '!V11 *#REF!,0) -> 0 | AA12: =IFERROR((#REF!/100) *'master data '!Y11 *#REF!,0) -> 0 | AB12: =SUM(G12:AA12) -> 53.22 | AC12: =AB12 /7 -> 7.6028571 | AD12: =AC12 - D12 -> -82.397143 | AE12: mg | AF12: =IFERROR(AC12/D12*100,"N/A") -> 8.447619 | AG12: =AC12 -E12 -> -492.39714 | AH12: mg | AI12: =AC12 /E12*100 -> 1.5205714
A13: D3 | B13: fat | C13: iu | D13: 600 | E13: 2000 | G13: =IFERROR((inputs!$B$5/100) *'master data '!E12 * inputs!$D$5,0) -> 0 | H13: =IFERROR((inputs!$B$6/100) *'master data '!F12 * inputs!$D$6,0) -> 126 | I13: =IFERROR((inputs!$B$7/100) *'master data '!G12 * inputs!$D$7,0) -> 0 | J13: =IFERROR((inputs!$G$6/100) *'master data '!H12 * inputs!$I$6,0) -> 0 | K13: =IFERROR((inputs!$G$7/100) *'master data '!I12 * inputs!$I$7,0) -> 0 | L13: =IFERROR((inputs!$G$8/100) *'master data '!J12 * inputs!$I$8,0) -> 0 | M13: =IFERROR((inputs!$G$10/100) *'master data '!K12 * inputs!$I$10,0) -> 360.8 | N13: =IFERROR((inputs!$G$11/100) *'master data '!L12 * inputs!$I$11,0) -> 0.8 | O13: =IFERROR((inputs!$B$15/100) *'master data '!M12 * inputs!$D$15,0) -> 0 | P13: =IFERROR((inputs!$B$9/100) *'master data '!N12 * inputs!$D$9,0) -> 0 | Q13: =IFERROR((inputs!$G$5/100) *'master data '!O12 * inputs!$I$5,0) -> 0 | R13: =IFERROR((inputs!$B$10/100) *'master data '!P12 * inputs!$D$10,0) -> 0 | S13: =IFERROR((inputs!$B$11/100) *'master data '!Q12 * inputs!$D$11,0) -> 0 | T13: =IFERROR((inputs!$B$12/100) *'master data '!R12 * inputs!$D$12,0) -> 0 | U13: =IFERROR((inputs!$B$13/100) *'master data '!S12 * inputs!$D$13,0) -> 0 | V13: =IFERROR((inputs!$B$14/100) *'master data '!T12 * inputs!$D$14,0) -> 0 | W13: =IFERROR((#REF!/100) *'master data '!U12 *#REF!,0) -> 0 | X13: =IFERROR((#REF!/100) *'master data '!W12 *#REF!,0) -> 0 | Y13: =IFERROR((#REF!/100) *'master data '!X12 *#REF!,0) -> 0 | Z13: =IFERROR((#REF!/100) *'master data '!V12 *#REF!,0) -> 0 | AA13: =IFERROR((#REF!/100) *'master data '!Y12 *#REF!,0) -> 0 | AB13: =SUM(G13:AA13) -> 487.6 | AC13: =AB13 /7 -> 69.657143 | AD13: =AC13 - D13 -> -530.34286 | AE13: iu | AF13: =IFERROR(AC13/D13*100,"N/A") -> 11.609524 | AG13: =AC13 -E13 -> -1930.3429 | AH13: iu | AI13: =AC13 /E13*100 -> 3.4828571
A14: E (alpha-tocopherol) | B14: fat | C14: mg | D14: 15 | E14: 100 | G14: =IFERROR((inputs!$B$5/100) *'master data '!E13 * inputs!$D$5,0) -> 0 | H14: =IFERROR((inputs!$B$6/100) *'master data '!F13 * inputs!$D$6,0) -> 0.735 | I14: =IFERROR((inputs!$B$7/100) *'master data '!G13 * inputs!$D$7,0) -> 0.14 | J14: =IFERROR((inputs!$G$6/100) *'master data '!H13 * inputs!$I$6,0) -> 0.84 | K14: =IFERROR((inputs!$G$7/100) *'master data '!I13 * inputs!$I$7,0) -> 1.75 | L14: =IFERROR((inputs!$G$8/100) *'master data '!J13 * inputs!$I$8,0) -> 0.21 | M14: =IFERROR((inputs!$G$10/100) *'master data '!K13 * inputs!$I$10,0) -> 8.8 | N14: =IFERROR((inputs!$G$11/100) *'master data '!L13 * inputs!$I$11,0) -> 2.4 | O14: =IFERROR((inputs!$B$15/100) *'master data '!M13 * inputs!$D$15,0) -> 2.25 | P14: =IFERROR((inputs!$B$9/100) *'master data '!N13 * inputs!$D$9,0) -> 1.5 | Q14: =IFERROR((inputs!$G$5/100) *'master data '!O13 * inputs!$I$5,0) -> 0 | R14: =IFERROR((inputs!$B$10/100) *'master data '!P13 * inputs!$D$10,0) -> 0.3 | S14: =IFERROR((inputs!$B$11/100) *'master data '!Q13 * inputs!$D$11,0) -> 0.35 | T14: =IFERROR((inputs!$B$12/100) *'master data '!R13 * inputs!$D$12,0) -> 0.25 | U14: =IFERROR((inputs!$B$13/100) *'master data '!S13 * inputs!$D$13,0) -> 0.3 | V14: =IFERROR((inputs!$B$14/100) *'master data '!T13 * inputs!$D$14,0) -> 0.25 | W14: =IFERROR((#REF!/100) *'master data '!U13 *#REF!,0) -> 0 | X14: =IFERROR((#REF!/100) *'master data '!W13 *#REF!,0) -> 0 | Y14: =IFERROR((#REF!/100) *'master data '!X13 *#REF!,0) -> 0 | Z14: =IFERROR((#REF!/100) *'master data '!V13 *#REF!,0) -> 0 | AA14: =IFERROR((#REF!/100) *'master data '!Y13 *#REF!,0) -> 0 | AB14: =SUM(G14:AA14) -> 20.075 | AC14: =AB14 /7 -> 2.8678571 | AD14: =AC14 - D14 -> -12.132143 | AE14: mg | AF14: =IFERROR(AC14/D14*100,"N/A") -> 19.119048 | AG14: =AC14 -E14 -> -97.132143 | AH14: mg | AI14: =AC14 /E14*100 -> 2.8678571
... A16: K2 | B16: fat | C16: mcg | D16: 90 | E16: 150 | G16: =IFERROR((inputs!$B$5/100) *'master data '!E15 * inputs!$D$5,0) -> 0 | H16: =IFERROR((inputs!$B$6/100) *'master data '!F15 * inputs!$D$6,0) -> 10.5 | I16: =IFERROR((inputs!$B$7/100) *'master data '!G15 * inputs!$D$7,0) -> 0 | J16: =IFERROR((inputs!$G$6/100) *'master data '!H15 * inputs!$I$6,0) -> 0 | K16: =IFERROR((inputs!$G$7/100) *'master data '!I15 * inputs!$I$7,0) -> 0 | L16: =IFERROR((inputs!$G$8/100) *'master data '!J15 * inputs!$I$8,0) -> 0 | M16: =IFERROR((inputs!$G$10/100) *'master data '!K15 * inputs!$I$10,0) -> 1.32 | N16: =IFERROR((inputs!$G$11/100) *'master data '!L15 * inputs!$I$11,0) -> 0 | O16: =IFERROR((inputs!$B$15/100) *'master data '!M15 * inputs!$D$15,0) -> 0 | P16: =IFERROR((inputs!$B$9/100) *'master data '!N15 * inputs!$D$9,0) -> 0 | Q16: =IFERROR((inputs!$G$5/100) *'master data '!O15 * inputs!$I$5,0) -> 0 | R16: =IFERROR((inputs!$B$10/100) *'master data '!P15 * inputs!$D$10,0) -> 0 | S16: =IFERROR((inputs!$B$11/100) *'master data '!Q15 * inputs!$D$11,0) -> 0 | T16: =IFERROR((inputs!$B$12/100) *'master data '!R15 * inputs!$D$12,0) -> 0 | U16: =IFERROR((inputs!$B$13/100) *'master data '!S15 * inputs!$D$13,0) -> 0 | V16: =IFERROR((inputs!$B$14/100) *'master data '!T15 * inputs!$D$14,0) -> 0 | W16: =IFERROR((#REF!/100) *'master data '!U15 *#REF!,0) -> 0 | X16: =IFERROR((#REF!/100) *'master data '!W15 *#REF!,0) -> 0 | Y16: =IFERROR((#REF!/100) *'master data '!X15 *#REF!,0) -> 0 | Z16: =IFERROR((#REF!/100) *'master data '!V15 *#REF!,0) -> 0 | AA16: =IFERROR((#REF!/100) *'master data '!Y15 *#REF!,0) -> 0 | AB16: =SUM(G16:AA16) -> 11.82 | AC16: =AB16 /7 -> 1.6885714 | AD16: =AC16 - D16 -> -88.311429 | AE16: mcg | AF16: =IFERROR(AC16/D16*100,"N/A") -> 1.8761905 | AG16: =AC16 -E16 -> -148.31143 | AH16: mcg | AI16: =AC16 /E16*100 -> 1.1257143
A18: calcium | B18: fat | C18: mg | D18: 1000 | E18: 1200 | G18: =IFERROR((inputs!$B$5/100) *'master data '!E17 * inputs!$D$5,0) -> 380 | H18: =IFERROR((inputs!$B$6/100) *'master data '!F17 * inputs!$D$6,0) -> 1260 | I18: =IFERROR((inputs!$B$7/100) *'master data '!G17 * inputs!$D$7,0) -> 1680 | J18: =IFERROR((inputs!$G$6/100) *'master data '!H17 * inputs!$I$6,0) -> 113.4 | K18: =IFERROR((inputs!$G$7/100) *'master data '!I17 * inputs!$I$7,0) -> 2208.5 | L18: =IFERROR((inputs!$G$8/100) *'master data '!J17 * inputs!$I$8,0) -> 178.5 | M18: =IFERROR((inputs!$G$10/100) *'master data '!K17 * inputs!$I$10,0) -> 246.4 | N18: =IFERROR((inputs!$G$11/100) *'master data '!L17 * inputs!$I$11,0) -> 88 | O18: =IFERROR((inputs!$B$15/100) *'master data '!M17 * inputs!$D$15,0) -> 875 | P18: =IFERROR((inputs!$B$9/100) *'master data '!N17 * inputs!$D$9,0) -> 475 | Q18: =IFERROR((inputs!$G$5/100) *'master data '!O17 * inputs!$I$5,0) -> 49 | R18: =IFERROR((inputs!$B$10/100) *'master data '!P17 * inputs!$D$10,0) -> 37.5 | S18: =IFERROR((inputs!$B$11/100) *'master data '!Q17 * inputs!$D$11,0) -> 62 | T18: =IFERROR((inputs!$B$12/100) *'master data '!R17 * inputs!$D$12,0) -> 34 | U18: =IFERROR((inputs!$B$13/100) *'master data '!S17 * inputs!$D$13,0) -> 41.5 | V18: =IFERROR((inputs!$B$14/100) *'master data '!T17 * inputs!$D$14,0) -> 28 | W18: =IFERROR((#REF!/100) *'master data '!U17 *#REF!,0) -> 0 | X18: =IFERROR((#REF!/100) *'master data '!W17 *#REF!,0) -> 0 | Y18: =IFERROR((#REF!/100) *'master data '!X17 *#REF!,0) -> 0 | Z18: =IFERROR((#REF!/100) *'master data '!V17 *#REF!,0) -> 0 | AA18: =IFERROR((#REF!/100) *'master data '!Y17 *#REF!,0) -> 0 | AB18: =SUM(G18:AA18) -> 7756.8 | AC18: =AB18 / 7 -> 1108.1143 | AD18: =AC18 -D18 -> 108.11429 | AE18: mg | AF18: =IFERROR(AC18/D18*100,"N/A") -> 110.81143 | AG18: =AC18 -E18 -> -91.885714 | AH18: mg | AI18: =AC18 /E18*100 -> 92.342857
A19: magnesium | B19: fat | C19: mg | D19: 400 | E19: 500 | G19: =IFERROR((inputs!$B$5/100) *'master data '!E18 * inputs!$D$5,0) -> 102 | H19: =IFERROR((inputs!$B$6/100) *'master data '!F18 * inputs!$D$6,0) -> 105 | I19: =IFERROR((inputs!$B$7/100) *'master data '!G18 * inputs!$D$7,0) -> 140 | J19: =IFERROR((inputs!$G$6/100) *'master data '!H18 * inputs!$I$6,0) -> 371.7 | K19: =IFERROR((inputs!$G$7/100) *'master data '!I18 * inputs!$I$7,0) -> 1172.5 | L19: =IFERROR((inputs!$G$8/100) *'master data '!J18 * inputs!$I$8,0) -> 274.4 | M19: =IFERROR((inputs!$G$10/100) *'master data '!K18 * inputs!$I$10,0) -> 48.4 | N19: =IFERROR((inputs!$G$11/100) *'master data '!L18 * inputs!$I$11,0) -> 232 | O19: =IFERROR((inputs!$B$15/100) *'master data '!M18 * inputs!$D$15,0) -> 700 | P19: =IFERROR((inputs!$B$9/100) *'master data '!N18 * inputs!$D$9,0) -> 400 | Q19: =IFERROR((inputs!$G$5/100) *'master data '!O18 * inputs!$I$5,0) -> 122.5 | R19: =IFERROR((inputs!$B$10/100) *'master data '!P18 * inputs!$D$10,0) -> 67.5 | S19: =IFERROR((inputs!$B$11/100) *'master data '!Q18 * inputs!$D$11,0) -> 69 | T19: =IFERROR((inputs!$B$12/100) *'master data '!R18 * inputs!$D$12,0) -> 61 | U19: =IFERROR((inputs!$B$13/100) *'master data '!S18 * inputs!$D$13,0) -> 70 | V19: =IFERROR((inputs!$B$14/100) *'master data '!T18 * inputs!$D$14,0) -> 60 | W19: =IFERROR((#REF!/100) *'master data '!U18 *#REF!,0) -> 0 | X19: =IFERROR((#REF!/100) *'master data '!W18 *#REF!,0) -> 0 | Y19: =IFERROR((#REF!/100) *'master data '!X18 *#REF!,0) -> 0 | Z19: =IFERROR((#REF!/100) *'master data '!V18 *#REF!,0) -> 0 | AA19: =IFERROR((#REF!/100) *'master data '!Y18 *#REF!,0) -> 0 | AB19: =SUM(G19:AA19) -> 3996 | AC19: =AB19 / 7 -> 570.85714 | AD19: =AC19 -D19 -> 170.85714 | AE19: mg | AF19: =IFERROR(AC19/D19*100,"N/A") -> 142.71429 | AG19: =AC19 -E19 -> 70.857143 | AH19: mg | AI19: =AC19 /E19*100 -> 114.17143
A20: phosphorous | B20: fat | C20: mg | D20: 700 | E20: 1000 | G20: =IFERROR((inputs!$B$5/100) *'master data '!E19 * inputs!$D$5,0) -> 246 | H20: =IFERROR((inputs!$B$6/100) *'master data '!F19 * inputs!$D$6,0) -> 945 | I20: =IFERROR((inputs!$B$7/100) *'master data '!G19 * inputs!$D$7,0) -> 1400 | J20: =IFERROR((inputs!$G$6/100) *'master data '!H19 * inputs!$I$6,0) -> 1098.3 | K20: =IFERROR((inputs!$G$7/100) *'master data '!I19 * inputs!$I$7,0) -> 3010 | L20: =IFERROR((inputs!$G$8/100) *'master data '!J19 * inputs!$I$8,0) -> 449.4 | M20: =IFERROR((inputs!$G$10/100) *'master data '!K19 * inputs!$I$10,0) -> 871.2 | N20: =IFERROR((inputs!$G$11/100) *'master data '!L19 * inputs!$I$11,0) -> 1680 | O20: =IFERROR((inputs!$B$15/100) *'master data '!M19 * inputs!$D$15,0) -> 1625 | P20: =IFERROR((inputs!$B$9/100) *'master data '!N19 * inputs!$D$9,0) -> 750 | Q20: =IFERROR((inputs!$G$5/100) *'master data '!O19 * inputs!$I$5,0) -> 563.5 | R20: =IFERROR((inputs!$B$10/100) *'master data '!P19 * inputs!$D$10,0) -> 202.5 | S20: =IFERROR((inputs!$B$11/100) *'master data '!Q19 * inputs!$D$11,0) -> 215 | T20: =IFERROR((inputs!$B$12/100) *'master data '!R19 * inputs!$D$12,0) -> 195 | U20: =IFERROR((inputs!$B$13/100) *'master data '!S19 * inputs!$D$13,0) -> 205 | V20: =IFERROR((inputs!$B$14/100) *'master data '!T19 * inputs!$D$14,0) -> 180 | W20: =IFERROR((#REF!/100) *'master data '!U19 *#REF!,0) -> 0 | X20: =IFERROR((#REF!/100) *'master data '!W19 *#REF!,0) -> 0 | Y20: =IFERROR((#REF!/100) *'master data '!X19 *#REF!,0) -> 0 | Z20: =IFERROR((#REF!/100) *'master data '!V19 *#REF!,0) -> 0 | AA20: =IFERROR((#REF!/100) *'master data '!Y19 *#REF!,0) -> 0 | AB20: =SUM(G20:AA20) -> 13635.9 | AC20: =AB20 / 7 -> 1947.9857 | AD20: =AC20 -D20 -> 1247.9857 | AE20: mg | AF20: =IFERROR(AC20/D20*100,"N/A") -> 278.28367 | AG20: =AC20 -E20 -> 947.98571 | AH20: mg | AI20: =AC20 /E20*100 -> 194.79857
A21: potassium | B21: water | C21: mg | D21: 3400 | E21: 4000 | G21: =IFERROR((inputs!$B$5/100) *'master data '!E20 * inputs!$D$5,0) -> 90 | H21: =IFERROR((inputs!$B$6/100) *'master data '!F20 * inputs!$D$6,0) -> 1575 | I21: =IFERROR((inputs!$B$7/100) *'master data '!G20 * inputs!$D$7,0) -> 2240 | J21: =IFERROR((inputs!$G$6/100) *'master data '!H20 * inputs!$I$6,0) -> 900.9 | K21: =IFERROR((inputs!$G$7/100) *'master data '!I20 * inputs!$I$7,0) -> 1424.5 | L21: =IFERROR((inputs!$G$8/100) *'master data '!J20 * inputs!$I$8,0) -> 569.1 | M21: =IFERROR((inputs!$G$10/100) *'master data '!K20 * inputs!$I$10,0) -> 607.2 | N21: =IFERROR((inputs!$G$11/100) *'master data '!L20 * inputs!$I$11,0) -> 2048 | O21: =IFERROR((inputs!$B$15/100) *'master data '!M20 * inputs!$D$15,0) -> 4250 | P21: =IFERROR((inputs!$B$9/100) *'master data '!N20 * inputs!$D$9,0) -> 2187.5 | Q21: =IFERROR((inputs!$G$5/100) *'master data '!O20 * inputs!$I$5,0) -> 563.5 | R21: =IFERROR((inputs!$B$10/100) *'master data '!P20 * inputs!$D$10,0) -> 575 | S21: =IFERROR((inputs!$B$11/100) *'master data '!Q20 * inputs!$D$11,0) -> 622.5 | T21: =IFERROR((inputs!$B$12/100) *'master data '!R20 * inputs!$D$12,0) -> 490 | U21: =IFERROR((inputs!$B$13/100) *'master data '!S20 * inputs!$D$13,0) -> 675 | V21: =IFERROR((inputs!$B$14/100) *'master data '!T20 * inputs!$D$14,0) -> 437.5 | W21: =IFERROR((#REF!/100) *'master data '!U20 *#REF!,0) -> 0 | X21: =IFERROR((#REF!/100) *'master data '!W20 *#REF!,0) -> 0 | Y21: =IFERROR((#REF!/100) *'master data '!X20 *#REF!,0) -> 0 | Z21: =IFERROR((#REF!/100) *'master data '!V20 *#REF!,0) -> 0 | AA21: =IFERROR((#REF!/100) *'master data '!Y20 *#REF!,0) -> 0 | AB21: =SUM(G21:AA21) -> 19255.7 | AC21: =AB21 / 7 -> 2750.8143 | AD21: =AC21 -D21 -> -649.18571 | AE21: mg | AF21: =IFERROR(AC21/D21*100,"N/A") -> 80.906303 | AG21: =AC21 -E21 -> -1249.1857 | AH21: mg | AI21: =AC21 /E21*100 -> 68.770357
A22: sodium | B22: water | C22: mg | D22: 1500 | E22: 2000 | G22: =IFERROR((inputs!$B$5/100) *'master data '!E21 * inputs!$D$5,0) -> 25 | H22: =IFERROR((inputs!$B$6/100) *'master data '!F21 * inputs!$D$6,0) -> 462 | I22: =IFERROR((inputs!$B$7/100) *'master data '!G21 * inputs!$D$7,0) -> 700 | J22: =IFERROR((inputs!$G$6/100) *'master data '!H21 * inputs!$I$6,0) -> 4.2 | K22: =IFERROR((inputs!$G$7/100) *'master data '!I21 * inputs!$I$7,0) -> 56 | L22: =IFERROR((inputs!$G$8/100) *'master data '!J21 * inputs!$I$8,0) -> 21 | M22: =IFERROR((inputs!$G$10/100) *'master data '!K21 * inputs!$I$10,0) -> 624.8 | N22: =IFERROR((inputs!$G$11/100) *'master data '!L21 * inputs!$I$11,0) -> 560 | O22: =IFERROR((inputs!$B$15/100) *'master data '!M21 * inputs!$D$15,0) -> 5 | P22: =IFERROR((inputs!$B$9/100) *'master data '!N21 * inputs!$D$9,0) -> 50 | Q22: =IFERROR((inputs!$G$5/100) *'master data '!O21 * inputs!$I$5,0) -> 9.8 | R22: =IFERROR((inputs!$B$10/100) *'master data '!P21 * inputs!$D$10,0) -> 6 | S22: =IFERROR((inputs!$B$11/100) *'master data '!Q21 * inputs!$D$11,0) -> 7.5 | T22: =IFERROR((inputs!$B$12/100) *'master data '!R21 * inputs!$D$12,0) -> 5 | U22: =IFERROR((inputs!$B$13/100) *'master data '!S21 * inputs!$D$13,0) -> 6 | V22: =IFERROR((inputs!$B$14/100) *'master data '!T21 * inputs!$D$14,0) -> 5 | W22: =IFERROR((#REF!/100) *'master data '!U21 *#REF!,0) -> 0 | X22: =IFERROR((#REF!/100) *'master data '!W21 *#REF!,0) -> 0 | Y22: =IFERROR((#REF!/100) *'master data '!X21 *#REF!,0) -> 0 | Z22: =IFERROR((#REF!/100) *'master data '!V21 *#REF!,0) -> 0 | AA22: =IFERROR((#REF!/100) *'master data '!Y21 *#REF!,0) -> 0 | AB22: =SUM(G22:AA22) -> 2547.3 | AC22: =AB22 / 7 -> 363.9 | AD22: =AC22 -D22 -> -1136.1 | AE22: mg | AF22: =IFERROR(AC22/D22*100,"N/A") -> 24.26 | AG22: =AC22 -E22 -> -1636.1 | AH22: mg | AI22: =AC22 /E22*100 -> 18.195
A24: iron | B24: fat | C24: mg | D24: 8 | E24: 15 | G24: =IFERROR((inputs!$B$5/100) *'master data '!E23 * inputs!$D$5,0) -> 0.3 | H24: =IFERROR((inputs!$B$6/100) *'master data '!F23 * inputs!$D$6,0) -> 1.05 | I24: =IFERROR((inputs!$B$7/100) *'master data '!G23 * inputs!$D$7,0) -> 0.42 | J24: =IFERROR((inputs!$G$6/100) *'master data '!H23 * inputs!$I$6,0) -> 9.87 | K24: =IFERROR((inputs!$G$7/100) *'master data '!I23 * inputs!$I$7,0) -> 26.95 | L24: =IFERROR((inputs!$G$8/100) *'master data '!J23 * inputs!$I$8,0) -> 3.99 | M24: =IFERROR((inputs!$G$10/100) *'master data '!K23 * inputs!$I$10,0) -> 7.92 | N24: =IFERROR((inputs!$G$11/100) *'master data '!L23 * inputs!$I$11,0) -> 5.6 | O24: =IFERROR((inputs!$B$15/100) *'master data '!M23 * inputs!$D$15,0) -> 39.25 | P24: =IFERROR((inputs!$B$9/100) *'master data '!N23 * inputs!$D$9,0) -> 17.5 | Q24: =IFERROR((inputs!$G$5/100) *'master data '!O23 * inputs!$I$5,0) -> 4.9 | R24: =IFERROR((inputs!$B$10/100) *'master data '!P23 * inputs!$D$10,0) -> 3.45 | S24: =IFERROR((inputs!$B$11/100) *'master data '!Q23 * inputs!$D$11,0) -> 3.6 | T24: =IFERROR((inputs!$B$12/100) *'master data '!R23 * inputs!$D$12,0) -> 3.75 | U24: =IFERROR((inputs!$B$13/100) *'master data '!S23 * inputs!$D$13,0) -> 4.1 | V24: =IFERROR((inputs!$B$14/100) *'master data '!T23 * inputs!$D$14,0) -> 3.1 | W24: =IFERROR((#REF!/100) *'master data '!U23 *#REF!,0) -> 0 | X24: =IFERROR((#REF!/100) *'master data '!W23 *#REF!,0) -> 0 | Y24: =IFERROR((#REF!/100) *'master data '!X23 *#REF!,0) -> 0 | Z24: =IFERROR((#REF!/100) *'master data '!V23 *#REF!,0) -> 0 | AA24: =IFERROR((#REF!/100) *'master data '!Y23 *#REF!,0) -> 0 | AB24: =SUM(G24:AA24) -> 135.75 | AC24: =AB24 / 7 -> 19.392857 | AD24: =AC24 -D24 -> 11.392857 | AE24: mg | AF24: =IFERROR(AC24/D24*100,"N/A") -> 242.41071 | AG24: =AC24 -E24 -> 4.3928571 | AH24: mg | AI24: =AC24 /E24*100 -> 129.28571
A25: zinc | B25: water | C25: mg | D25: 11 | E25: 15 | G25: =IFERROR((inputs!$B$5/100) *'master data '!E24 * inputs!$D$5,0) -> 3.6 | H25: =IFERROR((inputs!$B$6/100) *'master data '!F24 * inputs!$D$6,0) -> 4.2 | I25: =IFERROR((inputs!$B$7/100) *'master data '!G24 * inputs!$D$7,0) -> 4.9 | J25: =IFERROR((inputs!$G$6/100) *'master data '!H24 * inputs!$I$6,0) -> 7.35 | K25: =IFERROR((inputs!$G$7/100) *'master data '!I24 * inputs!$I$7,0) -> 16.1 | L25: =IFERROR((inputs!$G$8/100) *'master data '!J24 * inputs!$I$8,0) -> 3.01 | M25: =IFERROR((inputs!$G$10/100) *'master data '!K24 * inputs!$I$10,0) -> 5.72 | N25: =IFERROR((inputs!$G$11/100) *'master data '!L24 * inputs!$I$11,0) -> 8 | O25: =IFERROR((inputs!$B$15/100) *'master data '!M24 * inputs!$D$15,0) -> 12.25 | P25: =IFERROR((inputs!$B$9/100) *'master data '!N24 * inputs!$D$9,0) -> 7.75 | Q25: =IFERROR((inputs!$G$5/100) *'master data '!O24 * inputs!$I$5,0) -> 5.88 | R25: =IFERROR((inputs!$B$10/100) *'master data '!P24 * inputs!$D$10,0) -> 1.35 | S25: =IFERROR((inputs!$B$11/100) *'master data '!Q24 * inputs!$D$11,0) -> 1.45 | T25: =IFERROR((inputs!$B$12/100) *'master data '!R24 * inputs!$D$12,0) -> 1.25 | U25: =IFERROR((inputs!$B$13/100) *'master data '!S24 * inputs!$D$13,0) -> 1.4 | V25: =IFERROR((inputs!$B$14/100) *'master data '!T24 * inputs!$D$14,0) -> 1.3 | W25: =IFERROR((#REF!/100) *'master data '!U24 *#REF!,0) -> 0 | X25: =IFERROR((#REF!/100) *'master data '!W24 *#REF!,0) -> 0 | Y25: =IFERROR((#REF!/100) *'master data '!X24 *#REF!,0) -> 0 | Z25: =IFERROR((#REF!/100) *'master data '!V24 *#REF!,0) -> 0 | AA25: =IFERROR((#REF!/100) *'master data '!Y24 *#REF!,0) -> 0 | AB25: =SUM(G25:AA25) -> 85.51 | AC25: =AB25 / 7 -> 12.215714 | AD25: =AC25 -D25 -> 1.2157143 | AE25: mg | AF25: =IFERROR(AC25/D25*100,"N/A") -> 111.05195 | AG25: =AC25 -E25 -> -2.7842857 | AH25: mg | AI25: =AC25 /E25*100 -> 81.438095
A26: copper | B26: fat | C26: mcg | D26: 900 | E26: 1500 | G26: =IFERROR((inputs!$B$5/100) *'master data '!E25 * inputs!$D$5,0) -> 1.5 | H26: =IFERROR((inputs!$B$6/100) *'master data '!F25 * inputs!$D$6,0) -> 126 | I26: =IFERROR((inputs!$B$7/100) *'master data '!G25 * inputs!$D$7,0) -> 0.07 | J26: =IFERROR((inputs!$G$6/100) *'master data '!H25 * inputs!$I$6,0) -> 840 | K26: =IFERROR((inputs!$G$7/100) *'master data '!I25 * inputs!$I$7,0) -> 3220 | L26: =IFERROR((inputs!$G$8/100) *'master data '!J25 * inputs!$I$8,0) -> 854 | M26: =IFERROR((inputs!$G$10/100) *'master data '!K25 * inputs!$I$10,0) -> 316.8 | N26: =IFERROR((inputs!$G$11/100) *'master data '!L25 * inputs!$I$11,0) -> 320 | O26: =IFERROR((inputs!$B$15/100) *'master data '!M25 * inputs!$D$15,0) -> 3750 | P26: =IFERROR((inputs!$B$9/100) *'master data '!N25 * inputs!$D$9,0) -> 1600 | Q26: =IFERROR((inputs!$G$5/100) *'master data '!O25 * inputs!$I$5,0) -> 0.735 | R26: =IFERROR((inputs!$B$10/100) *'master data '!P25 * inputs!$D$10,0) -> 0.425 | S26: =IFERROR((inputs!$B$11/100) *'master data '!Q25 * inputs!$D$11,0) -> 0.475 | T26: =IFERROR((inputs!$B$12/100) *'master data '!R25 * inputs!$D$12,0) -> 0.375 | U26: =IFERROR((inputs!$B$13/100) *'master data '!S25 * inputs!$D$13,0) -> 0.45 | V26: =IFERROR((inputs!$B$14/100) *'master data '!T25 * inputs!$D$14,0) -> 0.35 | W26: =IFERROR((#REF!/100) *'master data '!U25 *#REF!,0) -> 0 | X26: =IFERROR((#REF!/100) *'master data '!W25 *#REF!,0) -> 0 | Y26: =IFERROR((#REF!/100) *'master data '!X25 *#REF!,0) -> 0 | Z26: =IFERROR((#REF!/100) *'master data '!V25 *#REF!,0) -> 0 | AA26: =IFERROR((#REF!/100) *'master data '!Y25 *#REF!,0) -> 0 | AB26: =SUM(G26:AA26) -> 11031.18 | AC26: =AB26 / 7 -> 1575.8829 | AD26: =AC26 -D26 -> 675.88286 | AE26: mcg | AF26: =IFERROR(AC26/D26*100,"N/A") -> 175.0981 | AG26: =AC26 -E26 -> 75.882857 | AH26: mcg | AI26: =AC26 /E26*100 -> 105.05886
A27: iodine | B27: fat | C27: mcg | D27: 150 | E27: 200 | G27: =IFERROR((inputs!$B$5/100) *'master data '!E26 * inputs!$D$5,0) -> 45 | H27: =IFERROR((inputs!$B$6/100) *'master data '!F26 * inputs!$D$6,0) -> 210 | I27: =IFERROR((inputs!$B$7/100) *'master data '!G26 * inputs!$D$7,0) -> 280 | J27: =IFERROR((inputs!$G$6/100) *'master data '!H26 * inputs!$I$6,0) -> 10.5 | K27: =IFERROR((inputs!$G$7/100) *'master data '!I26 * inputs!$I$7,0) -> 0 | L27: =IFERROR((inputs!$G$8/100) *'master data '!J26 * inputs!$I$8,0) -> 0 | M27: =IFERROR((inputs!$G$10/100) *'master data '!K26 * inputs!$I$10,0) -> 220 | N27: =IFERROR((inputs!$G$11/100) *'master data '!L26 * inputs!$I$11,0) -> 56 | O27: =IFERROR((inputs!$B$15/100) *'master data '!M26 * inputs!$D$15,0) -> 7.5 | P27: =IFERROR((inputs!$B$9/100) *'master data '!N26 * inputs!$D$9,0) -> 12.5 | Q27: =IFERROR((inputs!$G$5/100) *'master data '!O26 * inputs!$I$5,0) -> 0 | R27: =IFERROR((inputs!$B$10/100) *'master data '!P26 * inputs!$D$10,0) -> 1.5 | S27: =IFERROR((inputs!$B$11/100) *'master data '!Q26 * inputs!$D$11,0) -> 1.5 | T27: =IFERROR((inputs!$B$12/100) *'master data '!R26 * inputs!$D$12,0) -> 1.5 | U27: =IFERROR((inputs!$B$13/100) *'master data '!S26 * inputs!$D$13,0) -> 2 | V27: =IFERROR((inputs!$B$14/100) *'master data '!T26 * inputs!$D$14,0) -> 1.5 | W27: =IFERROR((#REF!/100) *'master data '!U26 *#REF!,0) -> 0 | X27: =IFERROR((#REF!/100) *'master data '!W26 *#REF!,0) -> 0 | Y27: =IFERROR((#REF!/100) *'master data '!X26 *#REF!,0) -> 0 | Z27: =IFERROR((#REF!/100) *'master data '!V26 *#REF!,0) -> 0 | AA27: =IFERROR((#REF!/100) *'master data '!Y26 *#REF!,0) -> 0 | AB27: =SUM(G27:AA27) -> 849.5 | AC27: =AB27 / 7 -> 121.35714 | AD27: =AC27 -D27 -> -28.642857 | AE27: mcg | AF27: =IFERROR(AC27/D27*100,"N/A") -> 80.904762 | AG27: =AC27 -E27 -> -78.642857 | AH27: mcg | AI27: =AC27 /E27*100 -> 60.678571
A28: selenium | B28: water | C28: mcg | D28: 55 | E28: 150 | G28: =IFERROR((inputs!$B$5/100) *'master data '!E27 * inputs!$D$5,0) -> 12 | H28: =IFERROR((inputs!$B$6/100) *'master data '!F27 * inputs!$D$6,0) -> 21 | I28: =IFERROR((inputs!$B$7/100) *'master data '!G27 * inputs!$D$7,0) -> 42 | J28: =IFERROR((inputs!$G$6/100) *'master data '!H27 * inputs!$I$6,0) -> 71.4 | K28: =IFERROR((inputs!$G$7/100) *'master data '!I27 * inputs!$I$7,0) -> 196 | L28: =IFERROR((inputs!$G$8/100) *'master data '!J27 * inputs!$I$8,0) -> 17.5 | M28: =IFERROR((inputs!$G$10/100) *'master data '!K27 * inputs!$I$10,0) -> 132 | N28: =IFERROR((inputs!$G$11/100) *'master data '!L27 * inputs!$I$11,0) -> 216 | O28: =IFERROR((inputs!$B$15/100) *'master data '!M27 * inputs!$D$15,0) -> 42.5 | P28: =IFERROR((inputs!$B$9/100) *'master data '!N27 * inputs!$D$9,0) -> 20 | Q28: =IFERROR((inputs!$G$5/100) *'master data '!O27 * inputs!$I$5,0) -> 34.3 | R28: =IFERROR((inputs!$B$10/100) *'master data '!P27 * inputs!$D$10,0) -> 3 | S28: =IFERROR((inputs!$B$11/100) *'master data '!Q27 * inputs!$D$11,0) -> 3.5 | T28: =IFERROR((inputs!$B$12/100) *'master data '!R27 * inputs!$D$12,0) -> 2.5 | U28: =IFERROR((inputs!$B$13/100) *'master data '!S27 * inputs!$D$13,0) -> 4 | V28: =IFERROR((inputs!$B$14/100) *'master data '!T27 * inputs!$D$14,0) -> 3 | W28: =IFERROR((#REF!/100) *'master data '!U27 *#REF!,0) -> 0 | X28: =IFERROR((#REF!/100) *'master data '!W27 *#REF!,0) -> 0 | Y28: =IFERROR((#REF!/100) *'master data '!X27 *#REF!,0) -> 0 | Z28: =IFERROR((#REF!/100) *'master data '!V27 *#REF!,0) -> 0 | AA28: =IFERROR((#REF!/100) *'master data '!Y27 *#REF!,0) -> 0 | AB28: =SUM(G28:AA28) -> 820.7 | AC28: =AB28 / 7 -> 117.24286 | AD28: =AC28 -D28 -> 62.242857 | AE28: mcg | AF28: =IFERROR(AC28/D28*100,"N/A") -> 213.16883 | AG28: =AC28 -E28 -> -32.757143 | AH28: mcg | AI28: =AC28 /E28*100 -> 78.161905
A29: chromium | B29: water | C29: mcg | D29: 35 | E29: 100 | G29: =IFERROR((inputs!$B$5/100) *'master data '!E28 * inputs!$D$5,0) -> 6.9 | H29: =IFERROR((inputs!$B$6/100) *'master data '!F28 * inputs!$D$6,0) -> 10.5 | I29: =IFERROR((inputs!$B$7/100) *'master data '!G28 * inputs!$D$7,0) -> 4.2 | J29: =IFERROR((inputs!$G$6/100) *'master data '!H28 * inputs!$I$6,0) -> 4.2 | K29: =IFERROR((inputs!$G$7/100) *'master data '!I28 * inputs!$I$7,0) -> 0.7 | L29: =IFERROR((inputs!$G$8/100) *'master data '!J28 * inputs!$I$8,0) -> 0.14 | M29: =IFERROR((inputs!$G$10/100) *'master data '!K28 * inputs!$I$10,0) -> 0.44 | N29: =IFERROR((inputs!$G$11/100) *'master data '!L28 * inputs!$I$11,0) -> 16 | O29: =IFERROR((inputs!$B$15/100) *'master data '!M28 * inputs!$D$15,0) -> 6.25 | P29: =IFERROR((inputs!$B$9/100) *'master data '!N28 * inputs!$D$9,0) -> 5 | Q29: =IFERROR((inputs!$G$5/100) *'master data '!O28 * inputs!$I$5,0) -> 9.8 | R29: =IFERROR((inputs!$B$10/100) *'master data '!P28 * inputs!$D$10,0) -> 6 | S29: =IFERROR((inputs!$B$11/100) *'master data '!Q28 * inputs!$D$11,0) -> 6.5 | T29: =IFERROR((inputs!$B$12/100) *'master data '!R28 * inputs!$D$12,0) -> 5.5 | U29: =IFERROR((inputs!$B$13/100) *'master data '!S28 * inputs!$D$13,0) -> 7 | V29: =IFERROR((inputs!$B$14/100) *'master data '!T28 * inputs!$D$14,0) -> 5 | W29: =IFERROR((#REF!/100) *'master data '!U28 *#REF!,0) -> 0 | X29: =IFERROR((#REF!/100) *'master data '!W28 *#REF!,0) -> 0 | Y29: =IFERROR((#REF!/100) *'master data '!X28 *#REF!,0) -> 0 | Z29: =IFERROR((#REF!/100) *#REF! *#REF!,0) -> 0 | AA29: =IFERROR((#REF!/100) *'master data '!Y28 *#REF!,0) -> 0 | AB29: =SUM(G29:AA29) -> 94.13 | AC29: =AB29 / 7 -> 13.447143 | AD29: =AC29 -D29 -> -21.552857 | AE29: mcg | AF29: =IFERROR(AC29/D29*100,"N/A") -> 38.420408 | AG29: =AC29 -E29 -> -86.552857 | AH29: mcg | AI29: =AC29 /E29*100 -> 13.447143
A30: manganese | B30: water | C30: mg | D30: 2 | E30: 4 | G30: =IFERROR((inputs!$B$5/100) *'master data '!E29 * inputs!$D$5,0) -> 1.2 | H30: =IFERROR((inputs!$B$6/100) *'master data '!F29 * inputs!$D$6,0) -> 0.21 | I30: =IFERROR((inputs!$B$7/100) *'master data '!G29 * inputs!$D$7,0) -> 0.14 | J30: =IFERROR((inputs!$G$6/100) *'master data '!H29 * inputs!$I$6,0) -> 7.56 | K30: =IFERROR((inputs!$G$7/100) *'master data '!I29 * inputs!$I$7,0) -> 9.45 | L30: =IFERROR((inputs!$G$8/100) *'master data '!J29 * inputs!$I$8,0) -> 1.75 | M30: =IFERROR((inputs!$G$10/100) *'master data '!K29 * inputs!$I$10,0) -> 0 | N30: =IFERROR((inputs!$G$11/100) *'master data '!L29 * inputs!$I$11,0) -> 0.16 | O30: =IFERROR((inputs!$B$15/100) *'master data '!M29 * inputs!$D$15,0) -> 5.5 | P30: =IFERROR((inputs!$B$9/100) *'master data '!N29 * inputs!$D$9,0) -> 4.5 | Q30: =IFERROR((inputs!$G$5/100) *'master data '!O29 * inputs!$I$5,0) -> 5.88 | R30: =IFERROR((inputs!$B$10/100) *'master data '!P29 * inputs!$D$10,0) -> 0.8 | S30: =IFERROR((inputs!$B$11/100) *'master data '!Q29 * inputs!$D$11,0) -> 0.9 | T30: =IFERROR((inputs!$B$12/100) *'master data '!R29 * inputs!$D$12,0) -> 0.75 | U30: =IFERROR((inputs!$B$13/100) *'master data '!S29 * inputs!$D$13,0) -> 0.8 | V30: =IFERROR((inputs!$B$14/100) *'master data '!T29 * inputs!$D$14,0) -> 0.7 | W30: =IFERROR((#REF!/100) *'master data '!U29 *#REF!,0) -> 0 | X30: =IFERROR((#REF!/100) *'master data '!W29 *#REF!,0) -> 0 | Y30: =IFERROR((#REF!/100) *'master data '!X29 *#REF!,0) -> 0 | Z30: =IFERROR((#REF!/100) *#REF! *#REF!,0) -> 0 | AA30: =IFERROR((#REF!/100) *'master data '!Y29 *#REF!,0) -> 0 | AB30: =SUM(G30:AA30) -> 40.3 | AC30: =AB30 / 7 -> 5.7571429 | AD30: =AC30 -D30 -> 3.7571429 | AE30: mg | AF30: =IFERROR(AC30/D30*100,"N/A") -> 287.85714 | AG30: =AC30 -E30 -> 1.7571429 | AH30: mg | AI30: =AC30 /E30*100 -> 143.92857
A31: molybdenum | B31: water | C31: mcg | D31: 45 | E31: 100 | G31: =IFERROR((inputs!$B$5/100) *'master data '!E30 * inputs!$D$5,0) -> 0 | H31: =IFERROR((inputs!$B$6/100) *'master data '!F30 * inputs!$D$6,0) -> 52.5 | I31: =IFERROR((inputs!$B$7/100) *'master data '!G30 * inputs!$D$7,0) -> 28 | J31: =IFERROR((inputs!$G$6/100) *'master data '!H30 * inputs!$I$6,0) -> 105 | K31: =IFERROR((inputs!$G$7/100) *'master data '!I30 * inputs!$I$7,0) -> 7 | L31: =IFERROR((inputs!$G$8/100) *'master data '!J30 * inputs!$I$8,0) -> 1.4 | M31: =IFERROR((inputs!$G$10/100) *'master data '!K30 * inputs!$I$10,0) -> 8.8 | N31: =IFERROR((inputs!$G$11/100) *'master data '!L30 * inputs!$I$11,0) -> 40 | O31: =IFERROR((inputs!$B$15/100) *'master data '!M30 * inputs!$D$15,0) -> 100 | P31: =IFERROR((inputs!$B$9/100) *'master data '!N30 * inputs!$D$9,0) -> 75 | Q31: =IFERROR((inputs!$G$5/100) *'master data '!O30 * inputs!$I$5,0) -> 196 | R31: =IFERROR((inputs!$B$10/100) *'master data '!P30 * inputs!$D$10,0) -> 65 | S31: =IFERROR((inputs!$B$11/100) *'master data '!Q30 * inputs!$D$11,0) -> 70 | T31: =IFERROR((inputs!$B$12/100) *'master data '!R30 * inputs!$D$12,0) -> 60 | U31: =IFERROR((inputs!$B$13/100) *'master data '!S30 * inputs!$D$13,0) -> 70 | V31: =IFERROR((inputs!$B$14/100) *'master data '!T30 * inputs!$D$14,0) -> 57.5 | W31: =IFERROR((#REF!/100) *'master data '!U30 *#REF!,0) -> 0 | X31: =IFERROR((#REF!/100) *'master data '!W30 *#REF!,0) -> 0 | Y31: =IFERROR((#REF!/100) *'master data '!X30 *#REF!,0) -> 0 | Z31: =IFERROR((#REF!/100) *#REF! *#REF!,0) -> 0 | AA31: =IFERROR((#REF!/100) *'master data '!Y30 *#REF!,0) -> 0 | AB31: =SUM(G31:AA31) -> 936.2 | AC31: =AB31 / 7 -> 133.74286 | AD31: =AC31 -D31 -> 88.742857 | AE31: mcg | AF31: =IFERROR(AC31/D31*100,"N/A") -> 297.20635 | AG31: =AC31 -E31 -> 33.742857 | AH31: mcg | AI31: =AC31 /E31*100 -> 133.74286
A32: fluoride | B32: fat | C32: mg | D32: 3 | E32: 4 | G32: =IFERROR((inputs!$B$5/100) *'master data '!E31 * inputs!$D$5,0) -> 0 | H32: =IFERROR((inputs!$B$6/100) *'master data '!F31 * inputs!$D$6,0) -> 0.105 | I32: =IFERROR((inputs!$B$7/100) *'master data '!G31 * inputs!$D$7,0) -> 35 | J32: =IFERROR((inputs!$G$6/100) *'master data '!H31 * inputs!$I$6,0) -> 0.42 | K32: =IFERROR((inputs!$G$7/100) *'master data '!I31 * inputs!$I$7,0) -> 0 | L32: =IFERROR((inputs!$G$8/100) *'master data '!J31 * inputs!$I$8,0) -> 0 | M32: =IFERROR((inputs!$G$10/100) *'master data '!K31 * inputs!$I$10,0) -> 0 | N32: =IFERROR((inputs!$G$11/100) *'master data '!L31 * inputs!$I$11,0) -> 0 | O32: =IFERROR((inputs!$B$15/100) *'master data '!M31 * inputs!$D$15,0) -> 0.75 | P32: =IFERROR((inputs!$B$9/100) *'master data '!N31 * inputs!$D$9,0) -> 0.5 | Q32: =IFERROR((inputs!$G$5/100) *'master data '!O31 * inputs!$I$5,0) -> 0 | R32: =IFERROR((inputs!$B$10/100) *'master data '!P31 * inputs!$D$10,0) -> 20 | S32: =IFERROR((inputs!$B$11/100) *'master data '!Q31 * inputs!$D$11,0) -> 22.5 | T32: =IFERROR((inputs!$B$12/100) *'master data '!R31 * inputs!$D$12,0) -> 19 | U32: =IFERROR((inputs!$B$13/100) *'master data '!S31 * inputs!$D$13,0) -> 21 | V32: =IFERROR((inputs!$B$14/100) *'master data '!T31 * inputs!$D$14,0) -> 18 | W32: =IFERROR((#REF!/100) *'master data '!U31 *#REF!,0) -> 0 | X32: =IFERROR((#REF!/100) *'master data '!W31 *#REF!,0) -> 0 | Y32: =IFERROR((#REF!/100) *'master data '!X31 *#REF!,0) -> 0 | Z32: =IFERROR((#REF!/100) *#REF! *#REF!,0) -> 0 | AA32: =IFERROR((#REF!/100) *'master data '!Y31 *#REF!,0) -> 0 | AB32: =SUM(G32:AA32) -> 137.275 | AC32: =AB32 / 7 -> 19.610714 | AD32: =AC32 -D32 -> 16.610714 | AE32: mg | AF32: =IFERROR(AC32/D32*100,"N/A") -> 653.69048 | AG32: =AC32 -E32 -> 15.610714 | AH32: mg | AI32: =AC32 /E32*100 -> 490.26786
A33: boron | B33: water | C33: mg | D33: 1 | E33: 2 | G33: =IFERROR((inputs!$B$5/100) *'master data '!E32 * inputs!$D$5,0) -> 0 | H33: =IFERROR((inputs!$B$6/100) *'master data '!F32 * inputs!$D$6,0) -> 2.1 | I33: =IFERROR((inputs!$B$7/100) *'master data '!G32 * inputs!$D$7,0) -> 0.14 | J33: =IFERROR((inputs!$G$6/100) *'master data '!H32 * inputs!$I$6,0) -> 1.89 | K33: =IFERROR((inputs!$G$7/100) *'master data '!I32 * inputs!$I$7,0) -> 0 | L33: =IFERROR((inputs!$G$8/100) *'master data '!J32 * inputs!$I$8,0) -> 0 | M33: =IFERROR((inputs!$G$10/100) *'master data '!K32 * inputs!$I$10,0) -> 0 | N33: =IFERROR((inputs!$G$11/100) *'master data '!L32 * inputs!$I$11,0) -> 0 | O33: =IFERROR((inputs!$B$15/100) *'master data '!M32 * inputs!$D$15,0) -> 1.25 | P33: =IFERROR((inputs!$B$9/100) *'master data '!N32 * inputs!$D$9,0) -> 1 | Q33: =IFERROR((inputs!$G$5/100) *'master data '!O32 * inputs!$I$5,0) -> 0.49 | R33: =IFERROR((inputs!$B$10/100) *'master data '!P32 * inputs!$D$10,0) -> 0.4 | S33: =IFERROR((inputs!$B$11/100) *'master data '!Q32 * inputs!$D$11,0) -> 0.45 | T33: =IFERROR((inputs!$B$12/100) *'master data '!R32 * inputs!$D$12,0) -> 0.35 | U33: =IFERROR((inputs!$B$13/100) *'master data '!S32 * inputs!$D$13,0) -> 0.4 | V33: =IFERROR((inputs!$B$14/100) *'master data '!T32 * inputs!$D$14,0) -> 0.3 | W33: =IFERROR((#REF!/100) *'master data '!U32 *#REF!,0) -> 0 | X33: =IFERROR((#REF!/100) *'master data '!W32 *#REF!,0) -> 0 | Y33: =IFERROR((#REF!/100) *'master data '!X32 *#REF!,0) -> 0 | Z33: =IFERROR((#REF!/100) *#REF! *#REF!,0) -> 0 | AA33: =IFERROR((#REF!/100) *'master data '!Y32 *#REF!,0) -> 0 | AB33: =SUM(G33:AA33) -> 8.77 | AC33: =AB33 / 7 -> 1.2528571 | AD33: =AC33 -D33 -> 0.25285714 | AE33: mg | AF33: =IFERROR(AC33/D33*100,"N/A") -> 125.28571 | AG33: =AC33 -E33 -> -0.74714286 | AH33: mg | AI33: =AC33 /E33*100 -> 62.642857
A34: silicon | B34: water | C34: mg | D34: 10 | E34: 20 | G34: =IFERROR((inputs!$B$5/100) *'master data '!E33 * inputs!$D$5,0) -> 0 | H34: =IFERROR((inputs!$B$6/100) *'master data '!F33 * inputs!$D$6,0) -> 3.15 | I34: =IFERROR((inputs!$B$7/100) *'master data '!G33 * inputs!$D$7,0) -> 1.4 | J34: =IFERROR((inputs!$G$6/100) *'master data '!H33 * inputs!$I$6,0) -> 12.6 | K34: =IFERROR((inputs!$G$7/100) *'master data '!I33 * inputs!$I$7,0) -> 0 | L34: =IFERROR((inputs!$G$8/100) *'master data '!J33 * inputs!$I$8,0) -> 0 | M34: =IFERROR((inputs!$G$10/100) *'master data '!K33 * inputs!$I$10,0) -> 0 | N34: =IFERROR((inputs!$G$11/100) *'master data '!L33 * inputs!$I$11,0) -> 0 | O34: =IFERROR((inputs!$B$15/100) *'master data '!M33 * inputs!$D$15,0) -> 10 | P34: =IFERROR((inputs!$B$9/100) *'master data '!N33 * inputs!$D$9,0) -> 5 | Q34: =IFERROR((inputs!$G$5/100) *'master data '!O33 * inputs!$I$5,0) -> 24.5 | R34: =IFERROR((inputs!$B$10/100) *'master data '!P33 * inputs!$D$10,0) -> 3.5 | S34: =IFERROR((inputs!$B$11/100) *'master data '!Q33 * inputs!$D$11,0) -> 4 | T34: =IFERROR((inputs!$B$12/100) *'master data '!R33 * inputs!$D$12,0) -> 3 | U34: =IFERROR((inputs!$B$13/100) *'master data '!S33 * inputs!$D$13,0) -> 3.5 | V34: =IFERROR((inputs!$B$14/100) *'master data '!T33 * inputs!$D$14,0) -> 3 | W34: =IFERROR((#REF!/100) *'master data '!U33 *#REF!,0) -> 0 | X34: =IFERROR((#REF!/100) *'master data '!W33 *#REF!,0) -> 0 | Y34: =IFERROR((#REF!/100) *'master data '!X33 *#REF!,0) -> 0 | Z34: =IFERROR((#REF!/100) *#REF! *#REF!,0) -> 0 | AA34: =IFERROR((#REF!/100) *'master data '!Y33 *#REF!,0) -> 0 | AB34: =SUM(G34:AA34) -> 73.65 | AC34: =AB34 / 7 -> 10.521429 | AD34: =AC34 -D34 -> 0.52142857 | AE34: mg | AF34: =IFERROR(AC34/D34*100,"N/A") -> 105.21429 | AG34: =AC34 -E34 -> -9.4785714 | AH34: mg | AI34: =AC34 /E34*100 -> 52.607143
A36: cal | B36: - | C36: cal | D36: 1500 | E36: 1800 | G36: =IFERROR((inputs!$B$5/100) *'master data '!E35 * inputs!$D$5,0) -> 369 | H36: =IFERROR((inputs!$B$6/100) *'master data '!F35 * inputs!$D$6,0) -> 703.5 | I36: =IFERROR((inputs!$B$7/100) *'master data '!G35 * inputs!$D$7,0) -> 504 | J36: =IFERROR((inputs!$G$6/100) *'master data '!H35 * inputs!$I$6,0) -> 816.9 | K36: =IFERROR((inputs!$G$7/100) *'master data '!I35 * inputs!$I$7,0) -> 1701 | L36: =IFERROR((inputs!$G$8/100) *'master data '!J35 * inputs!$I$8,0) -> 373.8 | M36: =IFERROR((inputs!$G$10/100) *'master data '!K35 * inputs!$I$10,0) -> 629.2 | N36: =IFERROR((inputs!$G$11/100) *'master data '!L35 * inputs!$I$11,0) -> 960 | O36: =IFERROR((inputs!$B$15/100) *'master data '!M35 * inputs!$D$15,0) -> 862.5 | P36: =IFERROR((inputs!$B$9/100) *'master data '!N35 * inputs!$D$9,0) -> 900 | Q36: =IFERROR((inputs!$G$5/100) *'master data '!O35 * inputs!$I$5,0) -> 1764 | R36: =IFERROR((inputs!$B$10/100) *'master data '!P35 * inputs!$D$10,0) -> 174 | S36: =IFERROR((inputs!$B$11/100) *'master data '!Q35 * inputs!$D$11,0) -> 173.5 | T36: =IFERROR((inputs!$B$12/100) *'master data '!R35 * inputs!$D$12,0) -> 176 | U36: =IFERROR((inputs!$B$13/100) *'master data '!S35 * inputs!$D$13,0) -> 166.5 | V36: =IFERROR((inputs!$B$14/100) *'master data '!T35 * inputs!$D$14,0) -> 182 | W36: =IFERROR((#REF!/100) *'master data '!U35 *#REF!,0) -> 0 | X36: =IFERROR((#REF!/100) *'master data '!W35 *#REF!,0) -> 0 | Y36: =IFERROR((#REF!/100) *'master data '!X35 *#REF!,0) -> 0 | Z36: =IFERROR((#REF!/100) *'master data '!V35 *#REF!,0) -> 0 | AA36: =IFERROR((#REF!/100) *'master data '!Y35 *#REF!,0) -> 0 | AB36: =SUM(G36:AA36) -> 10455.9 | AC36: =AB36 / 7 -> 1493.7 | AD36: =AC36 -D36 -> -6.3 | AE36: gm | AF36: =IFERROR(AC36/D36*100,"N/A") -> 99.58 | AG36: =AC36 -E36 -> -306.3 | AH36: gm | AI36: =AC36 /E36*100 -> 82.983333
A37: carbs | B37: - | C37: gm | D37: 130 | E37: 150 | G37: =IFERROR((inputs!$B$5/100) *'master data '!E36 * inputs!$D$5,0) -> 32.44 | H37: =IFERROR((inputs!$B$6/100) *'master data '!F36 * inputs!$D$6,0) -> 50.4 | I37: =IFERROR((inputs!$B$7/100) *'master data '!G36 * inputs!$D$7,0) -> 72.8 | J37: =IFERROR((inputs!$G$6/100) *'master data '!H36 * inputs!$I$6,0) -> 138.6 | K37: =IFERROR((inputs!$G$7/100) *'master data '!I36 * inputs!$I$7,0) -> 147 | L37: =IFERROR((inputs!$G$8/100) *'master data '!J36 * inputs!$I$8,0) -> 20.3 | M37: =IFERROR((inputs!$G$10/100) *'master data '!K36 * inputs!$I$10,0) -> 3.08 | N37: =IFERROR((inputs!$G$11/100) *'master data '!L36 * inputs!$I$11,0) -> 0 | O37: =IFERROR((inputs!$B$15/100) *'master data '!M36 * inputs!$D$15,0) -> 82.5 | P37: =IFERROR((inputs!$B$9/100) *'master data '!N36 * inputs!$D$9,0) -> 150 | Q37: =IFERROR((inputs!$G$5/100) *'master data '!O36 * inputs!$I$5,0) -> 382.2 | R37: =IFERROR((inputs!$B$10/100) *'master data '!P36 * inputs!$D$10,0) -> 29.5 | S37: =IFERROR((inputs!$B$11/100) *'master data '!Q36 * inputs!$D$11,0) -> 29.5 | T37: =IFERROR((inputs!$B$12/100) *'master data '!R36 * inputs!$D$12,0) -> 30 | U37: =IFERROR((inputs!$B$13/100) *'master data '!S36 * inputs!$D$13,0) -> 30.5 | V37: =IFERROR((inputs!$B$14/100) *'master data '!T36 * inputs!$D$14,0) -> 30.5 | W37: =IFERROR((#REF!/100) *'master data '!U36 *#REF!,0) -> 0 | X37: =IFERROR((#REF!/100) *'master data '!W36 *#REF!,0) -> 0 | Y37: =IFERROR((#REF!/100) *'master data '!X36 *#REF!,0) -> 0 | Z37: =IFERROR((#REF!/100) *'master data '!V36 *#REF!,0) -> 0 | AA37: =IFERROR((#REF!/100) *'master data '!Y36 *#REF!,0) -> 0 | AB37: =SUM(G37:AA37) -> 1229.32 | AC37: =AB37 / 7 -> 175.61714 | AD37: =AC37 -D37 -> 45.617143 | AE37: gm | AF37: =IFERROR(AC37/D37*100,"N/A") -> 135.09011 | AG37: =AC37 -E37 -> 25.617143 | AH37: gm | AI37: =AC37 /E37*100 -> 117.0781
